# Exceptions

Exceptions in Python are a mechanism for handling errors that occur during program execution. When an error occurs, Python raises an exception, which interrupts the normal flow of the program. If the exception is not handled, the program will terminate with an error message. Here's a detailed explanation of how exceptions work in Python, including how to handle them:

### Common Exceptions in Python

Python has many built-in exceptions, some of the most common ones include:

- `ValueError`: Raised when a function receives an argument of the right type but an inappropriate value.
- `TypeError`: Raised when an operation or function is applied to an object of inappropriate type.
- `IndexError`: Raised when a sequence subscript is out of range.
- `KeyError`: Raised when a dictionary key is not found.
- `ZeroDivisionError`: Raised when the second argument of a division or modulo operation is zero.
- `FileNotFoundError`: Raised when a file or directory is requested but doesnâ€™t exist.

### Raising Exceptions

You can raise exceptions in your own code using the `raise` statement.

```python
def divide(a, b):
    if b == 0:
        raise ZeroDivisionError("You cannot divide by zero.")
    return a / b

divide(10, 0)  # This will raise ZeroDivisionError
```

### Handling Exceptions

To handle exceptions, you use the `try...except` block. This allows you to catch and handle exceptions gracefully.

```python
try:
    result = 10 / 0
except ZeroDivisionError:
    print("Cannot divide by zero.")
```

### Multiple Except Blocks

You can catch multiple exceptions by using multiple `except` blocks.

```python
try:
    x = int(input("Enter a number: "))
    result = 10 / x
except ValueError:
    print("Invalid input. Please enter a valid number.")
except ZeroDivisionError:
    print("Cannot divide by zero.")
```

### Catching All Exceptions

To catch any exception, you can use a bare `except` statement. However, this is generally discouraged as it can make debugging more difficult.

```python
try:
    # Some code that may raise an exception
    result = 10 / 'a'
except:
    print("An error occurred.")
```

### Finally Block

A `finally` block can be used to specify code that should be run no matter what, whether an exception occurred or not.

```python
try:
    result = 10 / 0
except ZeroDivisionError:
    print("Cannot divide by zero.")
finally:
    print("This will always execute.")
```

### Else Block

An `else` block can be used to specify code that should run if no exceptions are raised in the `try` block.

```python
try:
    result = 10 / 2
except ZeroDivisionError:
    print("Cannot divide by zero.")
else:
    print("Division successful.")
finally:
    print("This will always execute.")
```

### Custom Exceptions

You can define your own exceptions by creating a class that inherits from the built-in `Exception` class.

```python
class MyCustomError(Exception):
    pass

def do_something():
    raise MyCustomError("Something went wrong!")

try:
    do_something()
except MyCustomError as e:
    print(e)
```

### Summary

- **Raising Exceptions**: Use `raise` to throw an exception.
- **Handling Exceptions**: Use `try...except` blocks to catch and handle exceptions.
- **Multiple Exceptions**: Use multiple `except` blocks to handle different types of exceptions.
- **Finally Block**: Code in a `finally` block runs regardless of whether an exception was raised.
- **Else Block**: Code in an `else` block runs if no exceptions are raised.
- **Custom Exceptions**: You can create your own exception types by subclassing `Exception`.

Understanding exceptions and how to handle them is crucial for writing robust and error-resistant Python code.

## The With Statement

In Python, the `with` statement is used to wrap the execution of a block of code within methods defined by a context manager. This allows for setup and cleanup actions to be taken automatically, which helps manage resources like file streams, database connections, and locks.

The general syntax of the `with` statement is:

```python
with expression as variable:
    # block of code
```

Here's a breakdown of the `with` statement:

1. **Expression**: This is typically a call to a context manager that returns a context object. The context manager must implement the `__enter__` and `__exit__` methods.

2. **Variable**: This is optional. If provided, it will be assigned the value returned by the `__enter__` method of the context manager.

3. **Block of Code**: The code within this block will be executed with the context set up by the context manager. After the block is executed, the `__exit__` method is called to clean up.

### Context Manager Example with Files

A common use of the `with` statement is for file handling. Without the `with` statement, you would need to manually open and close files, which could lead to errors if the file isn't closed properly:

```python
file = open('example.txt', 'r')
try:
    content = file.read()
finally:
    file.close()
```

Using the `with` statement simplifies this:

```python
with open('example.txt', 'r') as file:
    content = file.read()
# file is automatically closed after the block
```

### How it Works:

1. **Enter the Context**: The `open` function returns a file object that has `__enter__` and `__exit__` methods. The `__enter__` method is called and its return value is assigned to the variable `file`.

2. **Execute the Block**: The block of code inside the `with` statement is executed with the file object available.

3. **Exit the Context**: After the block execution is completed, the `__exit__` method is called, which closes the file.

### Creating a Custom Context Manager

You can create your own context manager by defining a class with `__enter__` and `__exit__` methods:

```python
class MyContextManager:
    def __enter__(self):
        print("Entering the context")
        return self

    def __exit__(self, exc_type, exc_val, exc_tb):
        print("Exiting the context")
        if exc_type is not None:
            print(f"An exception occurred: {exc_val}")
        return True  # To suppress the exception

# Using the custom context manager
with MyContextManager() as manager:
    print("Inside the context")
    raise ValueError("This is an error")
```

In this example:

- `__enter__` is called when the block starts, and it returns the context manager instance.
- `__exit__` is called when the block ends. It takes three arguments: exception type, exception value, and traceback. If no exception occurs, these are all `None`. Returning `True` suppresses the exception.

### Benefits of Using the `with` Statement

1. **Automatic Resource Management**: Ensures resources are released properly.
2. **Cleaner Code**: Reduces boilerplate code for setup and cleanup.
3. **Error Handling**: Handles exceptions gracefully within the context.

The `with` statement is a powerful tool in Python for managing resources and ensuring that they are properly cleaned up after use.
